Workbook

Sheet Inputs
A1: BreezeAI Accelerator in KLC AWS - Cost Calculator Inputs
A2: Blue cells are editable assumptions. Prices: AWS on-demand list, us-east-1 baseline, June 2026 - verify current prices and KLC region before sending externally.
A4: General
A5: Engagement duration | B5: 14 | C5: weeks | D5: SOW term; add buffer weeks here if environment runs longer
A6: Regional price multiplier | B6: 1 | C6: x | D6: 1.00 = us-east-1 baseline. eu-north-1 ≈ 1.04, us-west-2 ≈ 1.00 - set per KLC-designated region
A7: Weeks per month (constant) | B7: 4.345 | C7: wk/mo | D7: 365.25 / 12 / 7 - used to convert monthly run rate to engagement total
A8: Hours per month (constant) | B8: 730 | C8: hr/mo | D8: AWS billing convention
A10: Compute & network quantities
A11: EKS worker nodes | B11: 4 | C11: nodes | D11: IaC: min 1 / desired 4 / max 5 m5.2xlarge; 2 assumed for engagement workload
A12: Node instance rate (m5.2xlarge) | B12: 0.384 | C12: $/hr | D12: Source: AWS EC2 on-demand pricing, us-east-1, June 2026
A13: EKS control plane rate | B13: 0.1 | C13: $/hr | D13: Source: AWS EKS pricing - standard cluster
A14: Jump box rate (t3.micro) | B14: 0.0104 | C14: $/hr | D14: Source: AWS EC2 on-demand pricing
A15: ALB count | B15: 1 | C15: lb | D15: terraform/alb-asg - HTTPS entry
A16: ALB hourly rate | B16: 0.0225 | C16: $/hr | D16: Source: AWS ELB pricing
A17: ALB average LCUs | B17: 3 | C17: LCU | D17: Low-traffic internal tool estimate
A18: LCU rate | B18: 0.008 | C18: $/LCU-hr | D18: Source: AWS ELB pricing
A19: Classic LB count (Kong / Neo4j bolt) | B19: 2 | C19: lb | D19: Kong provisions a CLB; Neo4j bolt optional second - set 2 if both kept
A20: CLB hourly rate | B20: 0.025 | C20: $/hr | D20: Source: AWS ELB pricing
A21: NAT Gateway hourly rate | B21: 0.045 | C21: $/hr | D21: Source: AWS VPC pricing - single NAT
A22: NAT data processed | B22: 200 | C22: GB/mo | D22: Image pulls, repo ingestion, AWS API traffic - usage estimate
A23: NAT data rate | B23: 0.045 | C23: $/GB | D23: Source: AWS VPC pricing
A24: Inter-AZ transfer | B24: 20 | C24: GB/mo
A25: Inter-AZ rate | B25: 0.01 | C25: $/GB
A27: Storage & database
A28: EBS provisioned | B28: 250 | C28: GiB | D28: Node roots 2×70 + Neo4j 110 + Redis/misc - per IaC sizing
A29: EBS rate (gp3) | B29: 0.08 | C29: $/GiB-mo | D29: Source: AWS EBS pricing
A30: EFS stored (elastic, actual usage) | B30: 60 | C30: GiB | D30: ~120 GiB PVs provisioned; EFS bills actual bytes stored
A31: EFS rate (Standard) | B31: 0.3 | C31: $/GiB-mo | D31: Source: AWS EFS pricing
A32: RDS instance rate (db.t3.large, single-AZ) | B32: 0.136 | C32: $/hr | D32: Source: AWS RDS PostgreSQL on-demand pricing
A33: RDS storage | B33: 100 | C33: GiB | D33: terraform/postgres-rds: gp3 100 GiB initial (autoscales to 1 TB)
A34: RDS storage rate | B34: 0.115 | C34: $/GiB-mo | D34: Source: AWS RDS gp3 storage pricing
A35: S3 stored | B35: 50 | C35: GB | D35: Terraform state, backups, artifacts
A36: S3 rate (Standard) | B36: 0.023 | C36: $/GB-mo | D36: Source: AWS S3 pricing
A37: ECR stored | B37: 10 | C37: GB | D37: BreezeAI images
A38: ECR rate | B38: 0.1 | C38: $/GB-mo | D38: Source: AWS ECR pricing
A39: S3 PUT requests | B39: 1000 | C39: requests/mo
A40: PUT request rate | B40: 0.005 | C40: /1K requests
A41: S3 GET requests | B41: 5000 | C41: requests/mo
A42: GET request rate | B42: 0.0004 | C42: /1K requests
A44: Security & observability
...

Sheet Monthly Costs
A1: Monthly Run Rate - Infrastructure (before regional multiplier)
A2: All formulas reference Inputs. Fixed = runs regardless of usage. Usage = scales with activity (scenario multipliers apply on Summary).
A4: Line item | B4: Category | C4: Type | D4: Monthly cost
A5: EKS control plane | B5: Compute | C5: Fixed | D5: =Inputs!B13*Inputs!B8 -> 73
A6: EKS worker nodes (m5.2xlarge) | B6: Compute | C6: Fixed | D6: =Inputs!B11*Inputs!B12*Inputs!B8 -> 1121.28
A7: Jump box (t3.micro) | B7: Compute | C7: Fixed | D7: =Inputs!B14*Inputs!B8 -> 7.592
A8: Application Load Balancer + LCUs | B8: Network | C8: Fixed | D8: =Inputs!B15*(Inputs!B16+Inputs!B17*Inputs!B18)*Inputs!B8 -> 33.945
A9: Classic LB (Kong / Neo4j) | B9: Network | C9: Fixed | D9: =Inputs!B19*Inputs!B20*Inputs!B8 -> 36.5
A10: NAT Gateway (hourly) | B10: Network | C10: Fixed | D10: =Inputs!B21*Inputs!B8 -> 32.85
A11: NAT Gateway (data processed) | B11: Network | C11: Usage | D11: =Inputs!B22*Inputs!B23 -> 9
A12: Data transfer out | B12: Network | C12: Usage | D12: =Inputs!B61*Inputs!B62 -> 4.5
A13: EBS volumes (gp3) | B13: Storage | C13: Fixed | D13: =Inputs!B28*Inputs!B29 -> 20
A14: EFS (actual stored) | B14: Storage | C14: Usage | D14: =Inputs!B30*Inputs!B31 -> 18
A15: S3 | B15: Storage | C15: Usage | D15: =Inputs!B35*Inputs!B36 -> 1.15
A16: ECR image storage | B16: Storage | C16: Fixed | D16: =Inputs!B37*Inputs!B38 -> 1
A17: RDS PostgreSQL instance (single-AZ) | B17: Database | C17: Fixed | D17: =Inputs!B32*Inputs!B8 -> 99.28
A18: RDS storage (gp3) | B18: Database | C18: Fixed | D18: =Inputs!B33*Inputs!B34 -> 11.5
A19: Secrets Manager | B19: Security | C19: Fixed | D19: =Inputs!B45*Inputs!B46 -> 2
A20: KMS customer-managed keys | B20: Security | C20: Fixed | D20: =Inputs!B47*Inputs!B48 -> 2
A21: GuardDuty | B21: Security | C21: Usage | D21: =Inputs!B49 -> 10
A22: CloudWatch logs ingestion | B22: Observability | C22: Usage | D22: =Inputs!B50*Inputs!B51 -> 15
A23: CloudWatch alarms | B23: Observability | C23: Fixed | D23: =Inputs!B52*Inputs!B53 -> 3
A24: Container Insights metrics | B24: Observability | C24: Usage | D24: =Inputs!B60 -> 25
A25: CloudWatch log storage | B25: Observability | C25: Usage | D25: 0.9
A26: CloudWatch dashboards | B26: Observability | C26: Fixed | D26: 3
A27: CloudWatch custom metrics | B27: Observability | C27: Usage | D27: 15
A28: S3 requests | B28: Storage | C28: Usage | D28: 0.01
A31: Subtotal - Fixed | D31: =SUMIF(C5:C24,"Fixed",D5:D24) -> 1443.947
A32: Subtotal - Usage | D32: =SUMIF(C5:C24,"Usage",D5:D24) -> 82.65
A33: Total monthly infrastructure (us-east-1 baseline) | D33: =D31+D32 -> 1526.597

Sheet Engagement Summary
A1: Engagement Cost Summary - 14-Week BreezeAI Accelerator in KLC AWS
A2: Answers SOW comment: expected cost of running the AI accelerator in KLC's environment. Excludes Accion professional fees ($250,000 fixed, billed separately) and KLC-internal costs.
A4: Engagement months | B4: =Inputs!B5/Inputs!B7 -> 3.2220944
A6: Cost block | B6: Low | C6: Expected | D6: High | E6: Basis
A7: Infrastructure - fixed (EKS, nodes, RDS, LBs, NAT, EBS, KMS…) | B7: ='Monthly Costs'!D31*$B$4*Inputs!B6 -> 4652.5335 | C7: ='Monthly Costs'!D31*$B$4*Inputs!B6 -> 4652.5335 | D7: ='Monthly Costs'!D31*$B$4*Inputs!B6 -> 4652.5335 | E7: Fixed monthly × months × regional multiplier (scenario-independent)
A8: Infrastructure - usage (NAT data, logs, EFS, transfer, GuardDuty…) | B8: ='Monthly Costs'!D32*$B$4*Inputs!B6*Inputs!B75 -> 133.15305 | C8: ='Monthly Costs'!D32*$B$4*Inputs!B6*Inputs!B76 -> 266.3061 | D8: ='Monthly Costs'!D32*$B$4*Inputs!B6*Inputs!B77 -> 532.6122 | E8: Usage monthly × months × regional × scenario multiplier
A9: Bedrock - one-time corpus embedding | B9: =Inputs!B65*Inputs!B66/1000000*Inputs!B67*Inputs!B75 -> 0.15 | C9: =Inputs!B65*Inputs!B66/1000000*Inputs!B67*Inputs!B76 -> 0.3 | D9: =Inputs!B65*Inputs!B66/1000000*Inputs!B67*Inputs!B77 -> 0.6 | E9: docs × tokens/doc ÷ 1M × Titan rate × scenario
A10: Bedrock - LLM extraction (Claude 3 Haiku) | B10: =(Inputs!B68*Inputs!B70+Inputs!B68*Inputs!B69*Inputs!B71)*Inputs!B5*Inputs!B75 -> 140 | C10: =(Inputs!B68*Inputs!B70+Inputs!B68*Inputs!B69*Inputs!B71)*Inputs!B5*Inputs!B76 -> 280 | D10: =(Inputs!B68*Inputs!B70+Inputs!B68*Inputs!B69*Inputs!B71)*Inputs!B5*Inputs!B77 -> 560 | E10: (input Mtok × in-rate + output Mtok × out-rate) per week × weeks × scenario
A11: Bedrock - embedding refresh | B11: =Inputs!B72*Inputs!B67*Inputs!B5*Inputs!B75 -> 0.7 | C11: =Inputs!B72*Inputs!B67*Inputs!B5*Inputs!B76 -> 1.4 | D11: =Inputs!B72*Inputs!B67*Inputs!B5*Inputs!B77 -> 2.8 | E11: Mtok/wk × Titan rate × weeks × scenario
A12: TOTAL - engagement AWS cost | B12: =SUM(B7:B11) -> 4926.5365 | C12: =SUM(C7:C11) -> 5200.5396 | D12: =SUM(D7:D11) -> 5748.5457 | E12: Sum of blocks above
A13: ≈ per week | B13: =B12/Inputs!B5 -> 351.89547 | C13: =C12/Inputs!B5 -> 371.46711 | D13: =D12/Inputs!B5 -> 410.61041
A14: ≈ per month | B14: =B12/$B$4 -> 1528.9858 | C14: =C12/$B$4 -> 1614.0246 | D14: =D12/$B$4 -> 1784.1022
A16: Notes
A17: • Prices are AWS on-demand list (us-east-1 baseline, June 2026). Verify against the AWS pricing pages and the KLC-designated region before sending externally.
A18: • Excludes: Accion professional services fee ($250,000 fixed per SOW), KLC staff time, KLC enterprise tooling (Entra ID, Databricks), and any optional OpenAI usage.
A19: • Decommissioning at engagement end stops all charges; EFS/S3 snapshots can be retained for pennies per month if KLC wants the graph snapshot kept.
A20: • Neo4j runs in-cluster (no license cost - Community edition). AuraDB alternative would add ~$65–200/mo if KLC prefers managed.
A21: • Biggest levers: node count (Inputs!B11), LLM extraction volume (Inputs!B56), engagement weeks (Inputs!B5).
